<?xml version="1.0" encoding="UTF-8"?>
<!-- Generated by org.testng.reporters.JUnitReportReporter -->
<testsuite hostname="DESKTOP-MKTSV3B" failures="1" tests="2" name="com.index.LoginIndex" time="49.077" errors="0" timestamp="2021-10-13T15:06:41 IST" skipped="0">
  <testcase classname="com.index.LoginIndex" name="login" time="27.613"/>
  <system-out>
    <![CDATA[<br>Step 1 : Enter username.<br>
<br>Step2 : Enter password.<br>
<br>Step 3 : Click on Signin button.<br>
<br>Step 4 : Verify 'Login' is successful.<br>]]>
  </system-out>
  <testcase classname="com.index.LoginIndex" name="login_negative" time="21.464">
    <failure message="Login is not successful. expected [true] but found [false]" type="java.lang.AssertionError">
      <![CDATA[java.lang.AssertionError: Login is not successful. expected [true] but found [false]
at org.testng.Assert.fail(Assert.java:99)
at org.testng.Assert.failNotEquals(Assert.java:1037)
at org.testng.Assert.assertTrue(Assert.java:45)
at com.index.LoginIndex.login_negative(LoginIndex.java:74)
at java.base/jdk.internal.reflect.NativeMethodAccessorImpl.invoke0(Native Method)
at java.base/jdk.internal.reflect.NativeMethodAccessorImpl.invoke(NativeMethodAccessorImpl.java:78)
at java.base/jdk.internal.reflect.DelegatingMethodAccessorImpl.invoke(DelegatingMethodAccessorImpl.java:43)
at java.base/java.lang.reflect.Method.invoke(Method.java:567)
at org.testng.internal.MethodInvocationHelper.invokeMethod(MethodInvocationHelper.java:133)
at org.testng.internal.TestInvoker.invokeMethod(TestInvoker.java:598)
at org.testng.internal.TestInvoker.invokeTestMethod(TestInvoker.java:173)
at org.testng.internal.MethodRunner.runInSequence(MethodRunner.java:46)
at org.testng.internal.TestInvoker$MethodInvocationAgent.invoke(TestInvoker.java:824)
at org.testng.internal.TestInvoker.invokeTestMethods(TestInvoker.java:146)
at org.testng.internal.TestMethodWorker.invokeTestMethods(TestMethodWorker.java:146)
at org.testng.internal.TestMethodWorker.run(TestMethodWorker.java:128)
at java.base/java.util.ArrayList.forEach(ArrayList.java:1511)
at org.testng.TestRunner.privateRun(TestRunner.java:794)
at org.testng.TestRunner.run(TestRunner.java:596)
at org.testng.SuiteRunner.runTest(SuiteRunner.java:377)
at org.testng.SuiteRunner.runSequentially(SuiteRunner.java:371)
at org.testng.SuiteRunner.privateRun(SuiteRunner.java:332)
at org.testng.SuiteRunner.run(SuiteRunner.java:276)
at org.testng.SuiteRunnerWorker.runSuite(SuiteRunnerWorker.java:53)
at org.testng.SuiteRunnerWorker.run(SuiteRunnerWorker.java:96)
at org.testng.TestNG.runSuitesSequentially(TestNG.java:1212)
at org.testng.TestNG.runSuitesLocally(TestNG.java:1134)
at org.testng.TestNG.runSuites(TestNG.java:1063)
at org.testng.TestNG.run(TestNG.java:1031)
at org.testng.remote.AbstractRemoteTestNG.run(AbstractRemoteTestNG.java:115)
at org.testng.remote.RemoteTestNG.initAndRun(RemoteTestNG.java:251)
at org.testng.remote.RemoteTestNG.main(RemoteTestNG.java:77)
]]>
    </failure>
  </testcase> <!-- login_negative -->
  <system-out>
    <![CDATA[<br>Step 1 : Enter username.<br>
<br>Step 2 : Enter password.<br>
<br>Step 3 : Click on Signin button.<br>
<br>Step 4 : Verify 'Login' is successful.<br>
<br></br><Strong><font color=#ff0000>Fail                  </font></strong><img src='C:\Users\BAPS\eclipse-workspace\FrameworkDemo\report-imgs\fail.png' alt='fail' height='15' width='15'/>
<br><b><i>Failure Reason:</b></i>
<br><Strong><font color=#ff0000>java.lang.AssertionError: Login is not successful. expected [true] but found [false]</font></strong>]]>
  </system-out>
</testsuite> <!-- com.index.LoginIndex -->
